<?xml version="1.0" ?>
<!-- Copyright (c) 2013-2019 Fraunhofer IOSB, Karlsruhe, Germany. All rights reserved. -->
<robot name="WackerNeusonET18">
  <link name="base_link" />
  <joint name="chassis_rotation" type="continuous">
    <parent link="base_link"/>
    <child link="chassis"/>
    <origin rpy="0  0  0" xyz="0 0 0"/>
    <axis xyz="0  0  1"/>
    <limit effort="0" lower="0" upper="0" velocity="0.2"/>
  </joint>
  <joint name="blade_z" type="prismatic">
    <parent link="chassis"/>
    <child link="blade"/>
    <origin rpy="0 0 0" xyz="0.8775 0 -0.115"/>
    <axis xyz="0 0 1"/>
    <limit lower="0.13" upper="0.35" velocity="0.0" effort="0.0"/>
  </joint>
</robot>
