<?xml version="1.0" encoding="utf-8"?>
<!-- =================================================================================== -->
<!-- |    This document was autogenerated by xacro from e1_oilquick_bucket_raedlinger.urdf.xacro | -->
<!-- |    EDITING THIS FILE BY HAND IS NOT RECOMMENDED                                 | -->
<!-- =================================================================================== -->
<!-- Copyright (c) 2013-2017 Fraunhofer IOSB, Karlsruhe, Germany. All rights reserved. -->
<robot name="e1_oilquick_bucket_raedlinger">
  <material name="material_velodyne">
    <!--color rgba="0.5 0.5 0.55 1"/-->
    <!--color rgba="0.2 0.9 0.2 1"/-->
    <color rgba="0. 1. 0. 1"/>
  </material>
  <material name="material_box">
    <color rgba="0.8 0.8 0.8 0.8"/>
  </material>
  <material name="material_imugps">
    <!--color rgba="0.5 0.5 0.55 1"/-->
    <!--color rgba="0.2 0.9 0.2 1"/-->
    <color rgba="0. 1. 1. 1"/>
  </material>
  <material name="material_cylinder">
    <color rgba="0.3 0.3 0.3 1"/>
  </material>
  <material name="material_piston">
    <color rgba="0.8 0.8 0.8 1"/>
  </material>
  <link name="chassis">
    <inertial>
      <mass value="1500"/>
      <origin rpy="0  0  0" xyz="-0.534  0     0.686"/>
      <inertia ixx="0" ixy="0" ixz="0" iyy="0" iyz="0" izz="0"/>
    </inertial>
    <collision name="collision_undercarriage">
      <origin rpy="0  0  0" xyz="0     0     0.296"/>
      <geometry>
        <box size=".600 .840 .172"/>
      </geometry>
    </collision>
    <visual name="visual_undercarriage">
      <origin rpy="0  0  0" xyz="0     0     0.296"/>
      <geometry>
        <box size=".600 .840 .172"/>
      </geometry>
      <material name="material_cylinder"/>
    </visual>
    <collision name="collision_rotation_gear">
      <origin rpy="0 0 0" xyz="0 0 0.432"/>
      <geometry>
        <cylinder length=".1" radius=".20"/>
      </geometry>
    </collision>
    <visual name="visual_rotation_gear">
      <origin rpy="0 0 0" xyz="0 0 0.432"/>
      <geometry>
        <cylinder length=".1" radius=".20"/>
      </geometry>
      <material name="material_cylinder"/>
    </visual>
    <collision name="collision_track_tire_right">
      <origin rpy="0 0 0" xyz="-.110 -.535 .191"/>
      <geometry>
        <box size="1.605 .230 .382"/>
      </geometry>
    </collision>
    <visual name="visual_track_tire_right">
      <origin rpy="0 0 0" xyz="0.05 -.535 0"/>
      <geometry>
        <mesh filename="package://iosb/meshes/track_wheel.dae" scale="0.411 0.4 0.4"/>
      </geometry>
    </visual>
    <collision name="collision_track_tire_left">
      <origin rpy="0 0 0" xyz="-.110 .535 .191"/>
      <geometry>
        <box size="1.605 .230 .382"/>
      </geometry>
    </collision>
    <visual name="visual_track_tire_left">
      <origin rpy="0 0 0" xyz="0.05 .535 0"/>
      <geometry>
        <mesh filename="package://iosb/smeshes/track_wheel.dae" scale="0.411 0.4 0.4"/>
      </geometry>
    </visual>
    <collision name="collision_blade">
      <origin rpy="0 0 0" xyz="0.8775 0 0.075"/>
      <geometry>
        <box size="0.37 1.3 0.91"/>
      </geometry>
    </collision>
  </link>
  <link name="cabin">
    <collision name="collision_cabin">
      <origin rpy="0 0 0" xyz="-.384 0 1.5"/>
      <geometry>
        <box size="1.50 1.1 2.1"/>
      </geometry>
    </collision>
    <visual name="visual_cabin">
      <origin rpy="0 0 1.5707" xyz="0 0 0.400"/>
      <geometry>
        <mesh filename="package://iosb/meshes/cabin.dae" scale="0.45 0.45 0.45"/>
      </geometry>
      <material name="material_velodyne"/>
    </visual>
  </link>
  <link name="intermediate_cabin_boom">
    <inertial>
      <mass value="10"/>
      <origin rpy="0  0  0" xyz="0.09  0    0.02"/>
      <inertia ixx="0" ixy="0" ixz="0" iyy="0" iyz="0" izz="0"/>
    </inertial>
    <collision name="collision">
      <origin rpy="0 0 0" xyz="0.07 -0.07 0.05"/>
      <geometry>
        <box size=".400 .40 .40"/>
      </geometry>
    </collision>
    <visual name="visual">
      <origin rpy="0  0  0" xyz="0     0    -0.002"/>
      <geometry>
        <mesh filename="package://iosb/meshes/intermediate.dae" scale="0.45 0.45 0.45"/>
      </geometry>
    </visual>
  </link>
  <link name="boom">
    <inertial>
      <mass value="50"/>
      <origin rpy="0  0  0" xyz="0.14   0     0.935"/>
      <inertia ixx="0" ixy="0" ixz="0" iyy="0" iyz="0" izz="0"/>
    </inertial>
    <collision name="collision_boom_1">
      <origin rpy="0 -0.05 0" xyz="-0.0 0 0.57"/>
      <geometry>
        <box size=".350 .250 1.200"/>
      </geometry>
    </collision>
    <collision name="collision_boom_2">
      <origin rpy="0 0.8224 0" xyz="0.3 0 1.38"/>
      <geometry>
        <box size=".300 .250 1.05"/>
      </geometry>
    </collision>
    <collision name="velodyne_boom_c">
      <origin rpy="1.67339 -0.544965 3.09109" xyz="0.266848 0.0019812 1.03801"/>
      <geometry>
        <cylinder length="0.12" radius="0.08"/>
      </geometry>
    </collision>
    <visual name="visual_boom">
      <origin rpy="0      -0.02    -3.14158" xyz="0  0  0"/>
      <geometry>
        <mesh filename="package://iosb/meshes/boom.dae" scale="1.1 1.1 1.1"/>
      </geometry>
    </visual>
  </link>
  <link name="stick">
    <inertial>
      <mass value="30"/>
      <origin rpy="0  0  0" xyz="0.495  0     0.31"/>
      <inertia ixx="0" ixy="0" ixz="0" iyy="0" iyz="0" izz="0"/>
    </inertial>
    <collision name="stick">
      <origin rpy="0 1.018 0" xyz="0.375 0 0.34"/>
      <geometry>
        <box size=".30 .350 1.5"/>
      </geometry>
    </collision>
    <visual name="stick">
      <origin rpy="0     0.055  0" xyz="0  0  0"/>
      <geometry>
        <mesh filename="package://iosb/meshes/stick.dae" scale="0.42 0.43 0.45"/>
      </geometry>
    </visual>
  </link>
  <link name="base_link"/>
  <joint name="chassis_rotation" type="continuous">
    <parent link="base_link"/>
    <child link="chassis"/>
    <origin rpy="0  0  0" xyz="0 0 0"/>
    <axis xyz="0  0  1"/>
    <limit effort="0" lower="0" upper="0" velocity="0.2"/>
  </joint>
  <joint name="blade_z" type="prismatic">
    <parent link="chassis"/>
    <child link="blade"/>
    <origin rpy="0 0 0" xyz="0.8775 0 -0.115"/>
    <axis xyz="0 0 1"/>
    <limit effort="0.0" lower="0.13" upper="0.35" velocity="0.0"/>
  </joint>
  <joint name="cabin_rotation" type="continuous">
    <parent link="chassis"/>
    <child link="cabin"/>
    <origin rpy="0  0  0" xyz="0 0 0"/>
    <axis xyz="0  0  1"/>
    <limit effort="0" lower="-3.141" upper="3.141" velocity="1.05"/>
  </joint>
  <joint name="slewing_revolute" type="revolute">
    <parent link="cabin"/>
    <child link="intermediate_cabin_boom"/>
    <origin rpy="0  0  0" xyz="0.53    -0.044    0.57999"/>
    <axis xyz="0  0  1"/>
    <limit effort="0" lower="-0.78" upper="1.36" velocity="0.2"/>
  </joint>
  <joint name="boom_revolute" type="revolute">
    <parent link="intermediate_cabin_boom"/>
    <child link="boom"/>
    <origin rpy="0  0  0" xyz="0.095  0     0.18"/>
    <axis xyz="0  1  0"/>
    <limit effort="0" lower="0.0" upper="1.5" velocity="0.2"/>
  </joint>
  <joint name="stick_revolute" type="revolute">
    <parent link="boom"/>
    <child link="stick"/>
    <origin rpy="0  0  0" xyz="0.7    0     1.655"/>
    <axis xyz="0  1  0"/>
    <limit effort="0" lower="-0.02" upper="2" velocity="0.2"/>
  </joint>
  <joint name="slewing_prismatic" type="prismatic">
    <parent link="cylinder_slewing"/>
    <child link="piston_slewing"/>
    <origin rpy="0 0 0." xyz="0  0  0"/>
    <axis xyz="0  0  1"/>
    <limit effort="0.0" lower="0.4" upper="0.8" velocity="0.0"/>
  </joint>
  <joint name="boom_prismatic" type="prismatic">
    <parent link="cylinder_boom"/>
    <child link="piston_boom"/>
    <origin rpy="0 0.0  0" xyz="0  0  0"/>
    <axis xyz="0  0  1"/>
    <limit effort="0.0" lower="0.78" upper="1.14" velocity="0.0"/>
  </joint>
  <joint name="stick_prismatic" type="prismatic">
    <parent link="cylinder_stick"/>
    <child link="piston_stick"/>
    <origin rpy="0 0. 0" xyz="0  0  0"/>
    <axis xyz="0  0  1"/>
    <limit effort="0.0" lower="0.77" upper="1.23" velocity="0.0"/>
  </joint>
  <joint name="bucket_prismatic" type="prismatic">
    <parent link="cylinder_bucket"/>
    <child link="piston_bucket"/>
    <origin rpy="0 0 0" xyz="0  0  0"/>
    <axis xyz="0  0  1"/>
    <limit effort="0.0" lower="0.64" upper="0.983" velocity="0.0"/>
    <!--limit effort="0.0" lower="0.61" upper="1.02" velocity="0.0"/-->
    <!-- cylinder only 49cm, mit Gelenkpunkt 56cm, gemessen 2.218rad 93.5cm umgerechnet 97.0cm -->
    <!-- stick cylinder 68cm, boom 64cm mit Gelenkpunkt -->
    <!-- gemessen min/max 63.5cm, 98.0cm, umgerechnet alt 60.4cm, 100.9cm -->
  </joint>
  <joint name="cylinder_slewing" type="revolute">
    <parent link="cabin"/>
    <child link="cylinder_slewing"/>
    <origin rpy="-0.4 1.5707  0.1098" xyz="-0.05 -0.36 0.54"/>
    <axis xyz="1  0  0"/>
    <limit effort="0" lower="0" upper="0" velocity="0.1"/>
  </joint>
  <joint name="cylinder_boom" type="revolute">
    <parent link="intermediate_cabin_boom"/>
    <child link="cylinder_boom"/>
    <origin rpy="0  -0.55  0" xyz="0.21  0   -0.02"/>
    <axis xyz="0  1  0"/>
    <limit effort="0" lower="0" upper="0" velocity="0.1"/>
  </joint>
  <joint name="cylinder_stick" type="revolute">
    <parent link="boom"/>
    <child link="cylinder_stick"/>
    <origin rpy="0 1.0276 0" xyz="-0.13   0     1.135"/>
    <axis xyz="0  -1  0"/>
    <limit effort="0" lower="0" upper="0" velocity="0.1"/>
  </joint>
  <joint name="cylinder_bucket" type="revolute">
    <parent link="stick"/>
    <child link="cylinder_bucket"/>
    <origin rpy="0  1.242  0" xyz="0.14   0     0.315"/>
    <axis xyz="0  -1  0"/>
    <limit effort="0" lower="0" upper="0" velocity="0.1"/>
  </joint>
  <joint name="bucket_lever" type="revolute">
    <parent link="stick"/>
    <child link="bucket_lever_1_link"/>
    <origin rpy="0  0.05  0" xyz="0.89    0       0.56499"/>
    <axis xyz="0  1  0"/>
    <limit effort="0" lower="0" upper="0" velocity="0.1"/>
  </joint>
  <link name="cylinder_slewing">
    <inertial>
      <mass value="5"/>
      <origin rpy="0  0  0" xyz="0.  0   0"/>
      <inertia ixx="0" ixy="0" ixz="0" iyy="0" iyz="0" izz="0"/>
    </inertial>
    <visual name="visual_c_slewing">
      <origin rpy="0 0 0" xyz="0. 0  0.06"/>
      <geometry>
        <cylinder length=".640" radius=".034"/>
      </geometry>
      <material name="material_cylinder"/>
    </visual>
  </link>
  <link name="piston_slewing">
    <inertial>
      <mass value="5"/>
      <origin rpy="0  0  0" xyz="-0. -0.0  0.22"/>
      <inertia ixx="0" ixy="0" ixz="0" iyy="0" iyz="0" izz="0"/>
    </inertial>
    <visual name="visual_p_slewing">
      <origin rpy="0 0 0" xyz="-0. -0.0  -0.24"/>
      <geometry>
        <cylinder length=".600" radius=".020"/>
      </geometry>
      <material name="material_piston"/>
    </visual>
  </link>
  <link name="cylinder_boom">
    <inertial>
      <mass value="10"/>
      <origin rpy="0  0  0" xyz="0.00    0       0.28999"/>
      <inertia ixx="0" ixy="0" ixz="0" iyy="0" iyz="0" izz="0"/>
    </inertial>
    <collision name="collision_cylinder_boom">
      <origin rpy="0     0.0  0" xyz="0.00    0       0.28999"/>
      <geometry>
        <cylinder length=".584" radius=".034"/>
      </geometry>
    </collision>
    <visual name="visual_cylinder_boom">
      <origin rpy="0     0.0  0" xyz="0.00    0       0.31799"/>
      <geometry>
        <cylinder length=".64" radius=".034"/>
      </geometry>
      <material name="material_cylinder"/>
    </visual>
  </link>
  <link name="piston_boom">
    <inertial>
      <mass value="5"/>
      <origin rpy="0  0  0" xyz="-0.00  0    0.8"/>
      <inertia ixx="0" ixy="0" ixz="0" iyy="0" iyz="0" izz="0"/>
    </inertial>
    <collision name="collision_piston_boom">
      <origin rpy="0     0.0  0" xyz="-0.00  0    -0.31"/>
      <geometry>
        <cylinder length=".600" radius=".020"/>
      </geometry>
    </collision>
    <visual name="visual_piston_boom">
      <origin rpy="0     0.0  0" xyz="-0.00  0    -0.31"/>
      <geometry>
        <cylinder length=".600" radius=".020"/>
      </geometry>
      <material name="material_piston"/>
    </visual>
  </link>
  <link name="cylinder_stick">
    <inertial>
      <mass value="10"/>
      <origin rpy="0  0  0" xyz="0.  0     0.201"/>
      <inertia ixx="0" ixy="0" ixz="0" iyy="0" iyz="0" izz="0"/>
    </inertial>
    <collision name="collision_cylinder_ds">
      <origin rpy="0      0  0" xyz="0.  0     0.261"/>
      <geometry>
        <cylinder length=".594" radius=".034"/>
      </geometry>
    </collision>
    <visual name="visual_cylinder_ds">
      <origin rpy="0      0  0" xyz="0.  0     0.304"/>
      <geometry>
        <cylinder length=".68" radius=".034"/>
      </geometry>
      <material name="material_cylinder"/>
    </visual>
  </link>
  <link name="piston_stick">
    <inertial>
      <mass value="5"/>
      <origin rpy="0  0  0" xyz="-0.  0    0.4"/>
      <inertia ixx="0" ixy="0" ixz="0" iyy="0" iyz="0" izz="0"/>
    </inertial>
    <collision name="collision_piston_ds">
      <origin rpy="0      0.  0" xyz="-0.  0    -0.34"/>
      <geometry>
        <cylinder length=".655" radius=".020"/>
      </geometry>
    </collision>
    <visual name="visual_piston_ds">
      <origin rpy="0      0.  0" xyz="-0.  0    -0.34"/>
      <geometry>
        <cylinder length=".655" radius=".020"/>
      </geometry>
      <material name="material_piston"/>
    </visual>
  </link>
  <link name="cylinder_bucket">
    <inertial>
      <mass value="8"/>
      <inertia ixx="0" ixy="0" ixz="0" iyy="0" iyz="0" izz="0"/>
    </inertial>
    <collision name="collision_cylinder_bucket">
      <origin rpy="0      0  0" xyz="0  0     0.204"/>
      <geometry>
        <cylinder length=".456" radius=".034"/>
      </geometry>
    </collision>
    <visual name="visual_cylinder_bucket">
      <origin rpy="0      0 0" xyz="0  0     0.256"/>
      <geometry>
        <cylinder length=".56" radius=".034"/>
      </geometry>
      <material name="material_cylinder"/>
    </visual>
  </link>
  <link name="piston_bucket">
    <inertial>
      <mass value="3"/>
      <inertia ixx="0" ixy="0" ixz="0" iyy="0" iyz="0" izz="0"/>
    </inertial>
    <collision name="collision_piston_bucket">
      <origin rpy="0      0 0" xyz="-0   0    -0.304"/>
      <geometry>
        <cylinder length=".602" radius=".020"/>
      </geometry>
    </collision>
    <visual name="visual_piston_bucket">
      <origin rpy="0      0  0" xyz="-0   0    -0.304"/>
      <geometry>
        <cylinder length=".602" radius=".020"/>
      </geometry>
      <material name="material_piston"/>
    </visual>
  </link>
  <link name="bucket_lever_1_link">
    <inertial>
      <mass value="1"/>
      <origin rpy="0  0  0" xyz="-0.2   0    0.05"/>
      <inertia ixx="0" ixy="0" ixz="0" iyy="0" iyz="0" izz="0"/>
    </inertial>
    <visual name="visual_bucket lever">
      <origin rpy="0  0  0" xyz="-0.2   0    0.05"/>
      <geometry>
        <mesh filename="package://iosb/meshes/lever.dae" scale="0.953 1 0.9"/>
      </geometry>
    </visual>
  </link>
  <link name="box">
    <visual name="visual_box">
      <origin rpy="0 0 0" xyz="0 0 0"/>
      <geometry>
        <mesh filename="package://iosb/meshes/universalbox.dae" scale="1 1 1"/>
        <!--outer dimensions: 0.6 0.6 0.25-->
      </geometry>
      <material name="material_box"/>
    </visual>
  </link>
  <joint name="box_j" type="fixed">
    <parent link="cabin"/>
    <child link="box"/>
    <origin rpy="0 0 0" xyz="-0.4 0.0 2.4005"/>
    <axis xyz="1  0  0"/>
    <limit effort="0" lower="0" upper="0" velocity="0"/>
  </joint>
  <link name="imu">
    <visual name="visual_imu">
      <origin rpy="0 0 0" xyz="0 0 0"/>
      <geometry>
        <cylinder length="0.073" radius="0.04"/>
      </geometry>
      <material name="material_imugps"/>
    </visual>
  </link>
  <joint name="imu_j" type="fixed">
    <parent link="cabin"/>
    <child link="imu"/>
    <origin rpy="0 0 0" xyz="-0.603 -0.19 2.33"/>
    <axis xyz="1  0  0"/>
    <limit effort="0" lower="0" upper="0" velocity="0"/>
  </joint>
  <link name="gps">
    <visual name="visual_gps">
      <origin rpy="0 0 0" xyz="0 0 0.01"/>
      <geometry>
        <cylinder length="0.02" radius="0.031"/>
      </geometry>
      <material name="material_imugps"/>
    </visual>
  </link>
  <joint name="gps_j" type="fixed">
    <parent link="cabin"/>
    <child link="gps"/>
    <origin rpy="0 0 0" xyz="-0.3060 0.05 2.513"/>
    <axis xyz="1  0  0"/>
    <limit effort="0" lower="0" upper="0" velocity="0"/>
  </joint>
  <link name="trimble_gps">
    <visual name="visual_trimble_gps">
      <origin rpy="0 0 0" xyz="0 0 0.01"/>
      <geometry>
        <cylinder length="0.04" radius="0.072"/>
      </geometry>
      <material name="material_imugps"/>
    </visual>
  </link>
  <joint name="trimble_gps_j" type="fixed">
    <parent link="cabin"/>
    <child link="trimble_gps"/>
    <origin rpy="0 0 0" xyz="0.1340 0.45 2.483"/>
    <axis xyz="1  0  0"/>
    <limit effort="0" lower="0" upper="0" velocity="0"/>
  </joint>
  <link name="velodyne_boom">
    <collision name="velodyne_boom_c">
      <origin rpy="0 0 0" xyz="0 0 0"/>
      <geometry>
        <cylinder length="0.0717" radius="0.05165"/>
      </geometry>
    </collision>
    <visual name="visual_velodyne_boom">
      <origin rpy="0 0 0" xyz="0 0 0"/>
      <geometry>
        <cylinder length="0.0717" radius="0.05165"/>
      </geometry>
      <material name="material_velodyne"/>
    </visual>
  </link>
  <joint name="velodyne_boom_j" type="fixed">
    <parent link="boom"/>
    <child link="velodyne_boom"/>
    <origin rpy="1.5726 -0.574965  3.1415" xyz="0.266848 -0.02 1.03801"/>
    <!--origin xyz="0.266848 0.0019812 1.03801" rpy="1.5726 -0.574965  3.1415"/-->
    <!--origin xyz="0.053 0 1.0" rpy="1.5726 -0.52 3.14"/-->
    <!--origin xyz="0.266848 0.0019812 1.03801" rpy="1.67339 -0.544965 3.09109"/-->
    <!--origin xyz="0.23 0.0 1.03" rpy="1.59 -0.55 3.09"/-->
    <axis xyz="1  0  0"/>
    <limit effort="0" lower="0" upper="0" velocity="0.1"/>
  </joint>
  <link name="velodyne_left">
    <visual name="visual_velodyne_left">
      <origin rpy="0 0 0" xyz="0 0 0"/>
      <geometry>
        <cylinder length="0.0717" radius="0.05165"/>
      </geometry>
      <material name="material_velodyne"/>
    </visual>
    <collision name="collision_velodyne_left">
      <origin rpy="0 0 0" xyz="0 0 0"/>
      <geometry>
        <cylinder length="0.0717" radius="0.05165"/>
      </geometry>
    </collision>
  </link>
  <joint name="joint_velodyne_left" type="fixed">
    <parent link="cabin"/>
    <child link="velodyne_left"/>
    <origin rpy="0.403021 -0.052493 1.583287" xyz="0.511925 0.53 1.292254"/>
    <!--origin xyz="0.511925 0.53 1.302254" rpy="0.403021 -0.052493 1.583287"/-->
    <!--origin xyz="0.402031 0.544676 1.26314" rpy="0.401424 -0.055307 1.623144"/-->
    <!--origin xyz="0.441925 0.546301 1.262254" rpy="0.403021 -0.052493 1.583287"/-->
    <!--origin xyz="0.44 0.56 1.23" rpy="0.380 -0.029 1.545"/-->
    <!--origin xyz="0.40 0.56 1.23" rpy="0.380 -0.029 1.585"/-->
    <axis xyz="1  0  0"/>
    <limit effort="0" lower="0" upper="0" velocity="0"/>
  </joint>
  <link name="velodyne_right">
    <visual name="visual_velodyne_right">
      <origin rpy="0 0 0" xyz="0 0 0"/>
      <geometry>
        <cylinder length="0.0717" radius="0.05165"/>
      </geometry>
      <material name="material_velodyne"/>
    </visual>
    <collision name="collision_velodyne_right">
      <origin rpy="0 0 0" xyz="0 0 0"/>
      <geometry>
        <cylinder length="0.0717" radius="0.05165"/>
      </geometry>
    </collision>
  </link>
  <joint name="joint_velodyne_right" type="fixed">
    <parent link="cabin"/>
    <child link="velodyne_right"/>
    <origin rpy="0.327456 0.015904 1.598201" xyz="0.503 -0.53 1.2468"/>
    <!--origin xyz="0.40 -0.50 1.2" rpy="0.305 0.040 1.558"/-->
    <axis xyz="1  0  0"/>
    <limit effort="0" lower="0" upper="0" velocity="0"/>
  </joint>
  <link name="camera_link"/>
  <joint name="joint_camera_link" type="fixed">
    <parent link="quickcoupler"/>
    <child link="camera_link"/>
    <origin rpy="3.141 0.02 0.0" xyz="0.43 -0.0 0.005"/>
    <axis xyz="1  0  0"/>
    <limit effort="0" lower="0" upper="0" velocity="0"/>
  </joint>
  <link name="realsense_link"/>
  <joint name="joint_realsense_camera" type="fixed">
    <parent link="quickcoupler"/>
    <child link="realsense_link"/>
    <!--origin xyz="0.4 0.015 -0.03" rpy="0.0 -0.05 0.0"/-->
    <origin rpy="0.0 -0.05 0.0" xyz="0.39 0.025 -0.06"/>
    <axis xyz="1  0  0"/>
    <limit effort="0" lower="0" upper="0" velocity="0"/>
  </joint>
  <link name="blade"/>
  <link name="quickcoupler">
    <inertial>
      <mass value="25"/>
      <inertia ixx="0" ixy="0" ixz="0" iyy="0" iyz="0" izz="0"/>
    </inertial>
    <visual name="visual_quickcoupler">
      <geometry>
        <mesh filename="package://iosb/meshes/quickcoupler_oq40.dae" scale="1 1 1"/>
      </geometry>
    </visual>
    <collision name="collision_quickcoupler">
      <origin rpy="0 0 0" xyz="0.2 0 -0.1"/>
      <geometry>
        <box size="0.5 0.3 0.3"/>
      </geometry>
    </collision>
  </link>
  <link name="bucket_raedlinger">
    <inertial>
      <mass value="52"/>
      <origin rpy="0  0  0" xyz="-0.081 0 0.27"/>
      <inertia ixx="0" ixy="0" ixz="0" iyy="0" iyz="0" izz="0"/>
    </inertial>
    <visual name="visual_bucket">
      <origin rpy="0 0 0" xyz="0 0.0 0.0"/>
      <geometry>
        <mesh filename="package://iosb/meshes/bucket_raedlinger.dae" scale="1 1 1"/>
      </geometry>
    </visual>
    <collision name="collision_bucket">
      <origin rpy="0 -0.35 0" xyz="0.15 0.0 -0.25"/>
      <geometry>
        <box size="0.25 0.35 0.5"/>
      </geometry>
    </collision>
    <collision name="collision_bucket_tip">
      <origin rpy="0 -0.25 0" xyz="-0.05 0.0 -0.45"/>
      <geometry>
        <box size="0.3 0.35 0.25"/>
      </geometry>
    </collision>
    <collision name="collision_bucket_underpart">
      <origin rpy="0 -1.1 0" xyz="0.27 0.0 -0.24"/>
      <geometry>
        <box size="0.3 0.35 0.27"/>
      </geometry>
    </collision>
  </link>
  <joint name="quickcoupler_bucket_joint" type="fixed">
    <parent link="quickcoupler"/>
    <child link="bucket_raedlinger"/>
    <origin rpy="0 -0.034609879 0" xyz="0.044405 0.0 -0.126539"/>
    <axis xyz="0 1 0"/>
  </joint>
  <joint name="bucket_revolute" type="revolute">
    <parent link="stick"/>
    <child link="quickcoupler"/>
    <origin rpy="0 -2.65 0" xyz="0.996 0 0.615"/>
    <axis xyz="0  1  0"/>
    <limit effort="0" lower="-0.005246877670288086" upper="3.0338263511657715" velocity="0"/>
  </joint>
  <joint name="bucket_lever_3" type="revolute">
    <parent link="quickcoupler"/>
    <child link="bucket_lever_2"/>
    <origin rpy="0 0.25 0" xyz="0.144 0 0"/>
    <axis xyz="0 1 0"/>
    <limit effort="0" lower="0" upper="0" velocity="0"/>
  </joint>
  <link name="bucket_lever_2">
    <inertial>
      <mass value="1"/>
      <origin rpy="0  0  0" xyz="-0.09  0   -0.03"/>
      <inertia ixx="0" ixy="0" ixz="0" iyy="0" iyz="0" izz="0"/>
    </inertial>
    <visual name="visual_bucket_lever_2">
      <origin rpy="-3.14158 -0.05     0" xyz="-0.181  0    -0.06"/>
      <geometry>
        <mesh filename="package://iosb/meshes/lever.dae" scale="0.916 0.75 0.9"/>
      </geometry>
    </visual>
  </link>
</robot>

